<sdf version='1.6'>
  <world name='default'>
    <light name='sun' type='directional'>
      <cast_shadows>1</cast_shadows>
      <pose frame=''>0 0 10 0 -0 0</pose>
      <diffuse>0.8 0.8 0.8 1</diffuse>
      <specular>0.2 0.2 0.2 1</specular>
      <attenuation>
        <range>1000</range>
        <constant>0.9</constant>
        <linear>0.01</linear>
        <quadratic>0.001</quadratic>
      </attenuation>
      <direction>-0.5 0.1 -0.9</direction>
    </light>
    <model name='ground_plane'>
      <static>1</static>
      <link name='link'>
        <collision name='collision'>
          <geometry>
            <plane>
              <normal>0 0 1</normal>
              <size>100 100</size>
            </plane>
          </geometry>
          <surface>
            <contact>
              <collide_bitmask>65535</collide_bitmask>
              <ode/>
            </contact>
            <friction>
              <ode>
                <mu>100</mu>
                <mu2>50</mu2>
              </ode>
              <torsional>
                <ode/>
              </torsional>
            </friction>
            <bounce/>
          </surface>
          <max_contacts>10</max_contacts>
        </collision>
        <visual name='visual'>
          <cast_shadows>0</cast_shadows>
          <geometry>
            <plane>
              <normal>0 0 1</normal>
              <size>100 100</size>
            </plane>
          </geometry>
          <material>
            <script>
              <uri>file://media/materials/scripts/gazebo.material</uri>
              <name>Gazebo/Grey</name>
            </script>
          </material>
        </visual>
        <self_collide>0</self_collide>
        <enable_wind>0</enable_wind>
        <kinematic>0</kinematic>
      </link>
    </model>
    <gravity>0 0 -9.8</gravity>
    <magnetic_field>6e-06 2.3e-05 -4.2e-05</magnetic_field>
    <atmosphere type='adiabatic'/>
    <physics name='default_physics' default='0' type='ode'>
      <max_step_size>0.001</max_step_size>
      <real_time_factor>1</real_time_factor>
      <real_time_update_rate>1000</real_time_update_rate>
    </physics>
    <scene>
      <ambient>0.4 0.4 0.4 1</ambient>
      <background>0.7 0.7 0.7 1</background>
      <shadows>1</shadows>
    </scene>
    <audio>
      <device>default</device>
    </audio>
    <wind/>
    <spherical_coordinates>
      <surface_model>EARTH_WGS84</surface_model>
      <latitude_deg>0</latitude_deg>
      <longitude_deg>0</longitude_deg>
      <elevation>0</elevation>
      <heading_deg>0</heading_deg>
    </spherical_coordinates>
    <model name='serial3_robot_v3'>
      <link name='base_link'>
        <pose frame=''>0 0 0 0 -0 0</pose>
        <inertial>
          <pose frame=''>0.021781 -1e-06 0.020002 0 -0 0</pose>
          <mass>0.099185</mass>
          <inertia>
            <ixx>2.717e-05</ixx>
            <ixy>1.1961e-10</ixy>
            <ixz>8.6306e-08</ixz>
            <iyy>2.9447e-05</iyy>
            <iyz>1.1648e-12</iyz>
            <izz>4.9838e-05</izz>
          </inertia>
        </inertial>
        <collision name='base_link_collision'>
          <pose frame=''>0 0 0 0 -0 0</pose>
          <geometry>
            <mesh>
              <scale>1 1 1</scale>
              <uri>/home/johnsurface/catkin_ws/src/serial3_robot_v3/meshes/collision/base_link.STL</uri>
            </mesh>
          </geometry>
          <max_contacts>10</max_contacts>
          <surface>
            <contact>
              <ode/>
            </contact>
            <bounce/>
            <friction>
              <torsional>
                <ode/>
              </torsional>
              <ode/>
            </friction>
          </surface>
        </collision>
        <visual name='base_link_visual'>
          <pose frame=''>0 0 0 0 -0 0</pose>
          <geometry>
            <mesh>
              <scale>1 1 1</scale>
              <uri>/home/johnsurface/catkin_ws/src/serial3_robot_v3/meshes/visual/base_link.STL</uri>
            </mesh>
          </geometry>
        </visual>
        <self_collide>0</self_collide>
        <enable_wind>0</enable_wind>
        <kinematic>0</kinematic>
      </link>
      <joint name='joint_world' type='fixed'>
        <child>base_link</child>
        <parent>world</parent>
      </joint>
      <link name='e1_link'>
        <pose frame=''>0 0 0.04815 0 -0 0.025007</pose>
        <inertial>
          <pose frame=''>2e-06 0.002002 0.016219 0 -0 0</pose>
          <mass>0.010841</mass>
          <inertia>
            <ixx>3.3452e-06</ixx>
            <ixy>-1.561e-17</ixy>
            <ixz>1.5694e-10</ixz>
            <iyy>1.3848e-06</iyy>
            <iyz>6.927e-18</iyz>
            <izz>3.0336e-06</izz>
          </inertia>
        </inertial>
        <collision name='e1_link_collision'>
          <pose frame=''>0 0 0 0 -0 0</pose>
          <geometry>
            <mesh>
              <scale>1 1 1</scale>
              <uri>/home/johnsurface/catkin_ws/src/serial3_robot_v3/meshes/collision/e1_link.STL</uri>
            </mesh>
          </geometry>
          <max_contacts>10</max_contacts>
          <surface>
            <contact>
              <ode/>
            </contact>
            <bounce/>
            <friction>
              <torsional>
                <ode/>
              </torsional>
              <ode/>
            </friction>
          </surface>
        </collision>
        <visual name='e1_link_visual'>
          <pose frame=''>0 0 0 0 -0 0</pose>
          <geometry>
            <mesh>
              <scale>1 1 1</scale>
              <uri>/home/johnsurface/catkin_ws/src/serial3_robot_v3/meshes/visual/e1_link.STL</uri>
            </mesh>
          </geometry>
        </visual>
        <self_collide>0</self_collide>
        <enable_wind>0</enable_wind>
        <kinematic>0</kinematic>
      </link>
      <joint name='base_to_e1_joint' type='revolute'>
        <child>e1_link</child>
        <parent>base_link</parent>
        <axis>
          <xyz>0 0 -1</xyz>
          <limit>
            <lower>-1.5708</lower>
            <upper>1.5708</upper>
            <effort>77</effort>
            <velocity>1.43117</velocity>
          </limit>
          <dynamics>
            <spring_reference>0</spring_reference>
            <spring_stiffness>0</spring_stiffness>
          </dynamics>
          <use_parent_model_frame>1</use_parent_model_frame>
        </axis>
      </joint>
      <link name='e2_link'>
        <pose frame=''>-6e-06 0.00025 0.07865 1.5708 -1.5679 0.025007</pose>
        <inertial>
          <pose frame=''>0.1205 1e-06 -0.00071 0 -0 0</pose>
          <mass>0.094125</mass>
          <inertia>
            <ixx>8.4992e-06</ixx>
            <ixy>1.9769e-11</ixy>
            <ixz>-6.3555e-14</ixz>
            <iyy>2.1047e-05</iyy>
            <iyz>-7.3048e-15</iyz>
            <izz>2.3013e-05</izz>
          </inertia>
        </inertial>
        <collision name='e2_link_collision'>
          <pose frame=''>0 0 0 0 -0 0</pose>
          <geometry>
            <mesh>
              <scale>1 1 1</scale>
              <uri>/home/johnsurface/catkin_ws/src/serial3_robot_v3/meshes/collision/e2_link.STL</uri>
            </mesh>
          </geometry>
          <max_contacts>10</max_contacts>
          <surface>
            <contact>
              <ode/>
            </contact>
            <bounce/>
            <friction>
              <torsional>
                <ode/>
              </torsional>
              <ode/>
            </friction>
          </surface>
        </collision>
        <visual name='e2_link_visual'>
          <pose frame=''>0 0 0 0 -0 0</pose>
          <geometry>
            <mesh>
              <scale>1 1 1</scale>
              <uri>/home/johnsurface/catkin_ws/src/serial3_robot_v3/meshes/visual/e2_link.STL</uri>
            </mesh>
          </geometry>
        </visual>
        <self_collide>0</self_collide>
        <enable_wind>0</enable_wind>
        <kinematic>0</kinematic>
      </link>
      <joint name='e1_to_e2_joint' type='revolute'>
        <child>e2_link</child>
        <parent>e1_link</parent>
        <axis>
          <xyz>-0.025008 0.999687 0</xyz>
          <limit>
            <lower>-1.5708</lower>
            <upper>1.5708</upper>
            <effort>133</effort>
            <velocity>1.29154</velocity>
          </limit>
          <dynamics>
            <spring_reference>0</spring_reference>
            <spring_stiffness>0</spring_stiffness>
          </dynamics>
          <use_parent_model_frame>1</use_parent_model_frame>
        </axis>
      </joint>
      <link name='e3_link'>
        <pose frame=''>0.000686 1.7e-05 0.315649 -1.5708 -1.55603 -3.11658</pose>
        <inertial>
          <pose frame=''>0.045386 3e-06 0.000684 0 -0 0</pose>
          <mass>0.0117951</mass>
          <inertia>
            <ixx>3.04127e-06</ixx>
            <ixy>4.90518e-10</ixy>
            <ixz>1.37223e-07</ixz>
            <iyy>3.2328e-05</iyy>
            <iyz>-3.38363e-12</iyz>
            <izz>3.03183e-05</izz>
          </inertia>
        </inertial>
        <collision name='e3_link_collision'>
          <pose frame=''>0 0 0 0 -0 0</pose>
          <geometry>
            <mesh>
              <scale>1 1 1</scale>
              <uri>/home/johnsurface/catkin_ws/src/serial3_robot_v3/meshes/collision/e3_link.STL</uri>
            </mesh>
          </geometry>
          <max_contacts>10</max_contacts>
          <surface>
            <contact>
              <ode/>
            </contact>
            <bounce/>
            <friction>
              <torsional>
                <ode/>
              </torsional>
              <ode/>
            </friction>
          </surface>
        </collision>
        <collision name='e3_link_fixed_joint_lump__end_effector_collision_1'>
          <pose frame=''>0.18 0 0 0 -0 0</pose>
          <geometry>
            <mesh>
              <scale>1 1 1</scale>
              <uri>/home/johnsurface/catkin_ws/src/serial3_robot_v3/meshes/collision/end_effector.STL</uri>
            </mesh>
          </geometry>
          <max_contacts>10</max_contacts>
          <surface>
            <contact>
              <ode/>
            </contact>
            <bounce/>
            <friction>
              <torsional>
                <ode/>
              </torsional>
              <ode/>
            </friction>
          </surface>
        </collision>
        <visual name='e3_link_visual'>
          <pose frame=''>0 0 0 0 -0 0</pose>
          <geometry>
            <mesh>
              <scale>1 1 1</scale>
              <uri>/home/johnsurface/catkin_ws/src/serial3_robot_v3/meshes/visual/e3_link.STL</uri>
            </mesh>
          </geometry>
        </visual>
        <visual name='e3_link_fixed_joint_lump__end_effector_visual_1'>
          <pose frame=''>0.18 0 0 0 -0 0</pose>
          <geometry>
            <mesh>
              <scale>1 1 1</scale>
              <uri>/home/johnsurface/catkin_ws/src/serial3_robot_v3/meshes/visual/end_effector.STL</uri>
            </mesh>
          </geometry>
        </visual>
        <self_collide>0</self_collide>
        <enable_wind>0</enable_wind>
        <kinematic>0</kinematic>
      </link>
      <joint name='e2_to_e3_joint' type='revolute'>
        <child>e3_link</child>
        <parent>e2_link</parent>
        <axis>
          <xyz>-0.025008 0.999687 0</xyz>
          <limit>
            <lower>-1.5708</lower>
            <upper>1.5708</upper>
            <effort>66</effort>
            <velocity>2.1293</velocity>
          </limit>
          <dynamics>
            <spring_reference>0</spring_reference>
            <spring_stiffness>0</spring_stiffness>
          </dynamics>
          <use_parent_model_frame>1</use_parent_model_frame>
        </axis>
      </joint>
      <pose frame=''>0 0 0 0 -0 0</pose>
    </model>
    <state world_name='default'>
      <sim_time>50 19000000</sim_time>
      <real_time>56 963826483</real_time>
      <wall_time>1634073690 959505106</wall_time>
      <iterations>50019</iterations>
      <model name='ground_plane'>
        <pose frame=''>0 0 0 0 -0 0</pose>
        <scale>1 1 1</scale>
        <link name='link'>
          <pose frame=''>0 0 0 0 -0 0</pose>
          <velocity>0 0 0 0 -0 0</velocity>
          <acceleration>0 0 0 0 -0 0</acceleration>
          <wrench>0 0 0 0 -0 0</wrench>
        </link>
      </model>
      <model name='serial3_robot_v3'>
        <pose frame=''>-0 -0 0 -1e-06 4e-06 4e-06</pose>
        <scale>1 1 1</scale>
        <link name='base_link'>
          <pose frame=''>-0 -0 0 -1e-06 4e-06 4e-06</pose>
          <velocity>-1e-06 -1.1e-05 5e-06 -0.000967 0.000602 0.000103</velocity>
          <acceleration>0.021158 0.021304 -0.017044 -1.9292 1.20639 0.195246</acceleration>
          <wrench>0.002099 0.002113 -0.001691 0 -0 0</wrench>
        </link>
        <link name='e1_link'>
          <pose frame=''>-7e-06 -1e-06 0.04815 7e-06 5.7e-05 0.109953</pose>
          <velocity>7e-06 1.9e-05 1.7e-05 -0.001833 0.00159 -0.000334</velocity>
          <acceleration>0.066547 0.09782 0.027035 -0.809689 -0.581926 2.26841</acceleration>
          <wrench>0.000721 0.00106 0.000293 0 -0 0</wrench>
        </link>
        <link name='e2_link'>
          <pose frame=''>-3.9e-05 0.000247 0.078651 1.5708 -0.206371 0.109942</pose>
          <velocity>3.2e-05 7.1e-05 1.9e-05 -0.000681 0.000211 -0.000399</velocity>
          <acceleration>0.074976 0.057261 0.0311 -1.59951 -0.213831 -1.32323</acceleration>
          <wrench>0.007057 0.00539 0.002927 0 -0 0</wrench>
        </link>
        <link name='e3_link'>
          <pose frame=''>0.230557 0.025451 0.127229 1.57077 0.719429 0.10992</pose>
          <velocity>5.1e-05 1.6e-05 -3.9e-05 0.000424 -0.000124 -0.000219</velocity>
          <acceleration>0.062024 -0.016379 0.02234 -2.58153 1.17134 2.47966</acceleration>
          <wrench>0.000732 -0.000193 0.000263 0 -0 0</wrench>
        </link>
      </model>
      <light name='sun'>
        <pose frame=''>0 0 10 0 -0 0</pose>
      </light>
    </state>
    <gui fullscreen='0'>
      <camera name='user_camera'>
        <pose frame=''>0.476245 -0.525047 0.336259 0 0.399643 1.99219</pose>
        <view_controller>orbit</view_controller>
        <projection_type>perspective</projection_type>
      </camera>
    </gui>
  </world>
</sdf>
